<mujoco>
	<option timestep="0.0001" integrator="RK4" >
		<flag sensornoise="enable" energy="enable" />
	</option>


	<asset>
	  <texture type="skybox" builtin="gradient" rgb1="0.6 0.6 0.6" rgb2="0 0 0" width="512" height="512"/>

	  <texture name="texplane" type="2d" builtin="checker" rgb1=".25 .25 .25" rgb2=".3 .3 .3" width="512" height="512" mark="cross" markrgb=".8 .8 .8"/>

      <material name="matplane" reflectance="0.3" texture="texplane" texrepeat="1 1" texuniform="true"/>
	</asset>
	
	<worldbody>
        <light diffuse=".5 .5 .5" pos="0 0 3" dir="0 0 -1"/>
		<geom name="floor" pos="0 0 -2.1" size="0 0 1" type="plane" material="matplane"/>
		<light directional="true" diffuse=".8 .8 .8" specular=".2 .2 .2" pos="0 0 5" dir="0 0 -1"/>
		<body pos="0 0 0" euler="0 0 0">
			<joint name="pin" type="hinge" axis = "0 -1 0" pos="0 0 -0.5"/>
			<geom type="cylinder" size="0.05 0.5" rgba="0 .9 0 1" mass="1"/>
			<body pos="0 0.1 1" euler="0 0 0">
				<joint name="pin2" type="hinge" axis = "0 -1 0" pos="0 0 -0.5"/>
				<geom type="cylinder" size="0.05 0.5" rgba="0 0 .9 1" mass="1"/>
				<site name="endeff" pos="0 0 0.5" size="0.1"/>
			</body>
		</body>
	</worldbody>
	 <actuator>
		<motor joint="pin" name="torque" gear="1" ctrllimited="true" ctrlrange="-50 50" />
		<position name="position_servo" joint="pin" kp="0" />
		<velocity name="velocity_servo" joint="pin" kv="0" />
	</actuator>
	<sensor>
		<jointpos joint="pin" noise="0.2"/>
		<jointvel joint="pin" noise="1" />
	</sensor>
		 <actuator>
		<motor joint="pin2" name="torque2" gear="1" ctrllimited="true" ctrlrange="-50 50" />
		<position name="position_servo2" joint="pin2" kp="0" />
		<velocity name="velocity_servo2" joint="pin2" kv="0" />
	</actuator>
	<sensor>
		<jointpos joint="pin2" noise="0.2"/>
		<jointvel joint="pin2" noise="1" />
	</sensor>
</mujoco>
